2024-03-26 14:13:52,604 INFO    StreamThr :1607159 [internal.py:wandb_internal():86] W&B internal server running at pid: 1607159, started at: 2024-03-26 14:13:52.603999
2024-03-26 14:13:52,605 DEBUG   HandlerThread:1607159 [handler.py:handle_request():146] handle_request: status
2024-03-26 14:13:52,605 INFO    WriterThread:1607159 [datastore.py:open_for_write():87] open: /media/james/Projects/GitHub/DATA_340_NLP/Spring_2024/Lecture_Notebooks/wandb/run-20240326_141352-ndenuyhv/run-ndenuyhv.wandb
2024-03-26 14:13:52,606 DEBUG   SenderThread:1607159 [sender.py:send():379] send: header
2024-03-26 14:13:52,610 DEBUG   SenderThread:1607159 [sender.py:send():379] send: run
2024-03-26 14:13:52,788 ERROR   SenderThread:1607159 [internal_api.py:execute():373] 404 response executing GraphQL.
2024-03-26 14:13:52,788 ERROR   SenderThread:1607159 [internal_api.py:execute():374] {"errors":[{"message":"project not found","path":["upsertBucket"]}],"data":{"upsertBucket":null}}
2024-03-26 14:13:52,789 ERROR   SenderThread:1607159 [sender.py:send_run():971] It appears that you do not have permission to access the requested resource. Please reach out to the project owner to grant you access. If you have the correct permissions, verify that there are no issues with your networking setup.(Error 404: Not Found)
Traceback (most recent call last):
  File "/media/james/Projects/GitHub/DATA_340_NLP/venv/lib/python3.10/site-packages/wandb/sdk/lib/retry.py", line 131, in __call__
    result = self._call_fn(*args, **kwargs)
  File "/media/james/Projects/GitHub/DATA_340_NLP/venv/lib/python3.10/site-packages/wandb/sdk/internal/internal_api.py", line 369, in execute
    return self.client.execute(*args, **kwargs)  # type: ignore
  File "/media/james/Projects/GitHub/DATA_340_NLP/venv/lib/python3.10/site-packages/wandb/vendor/gql-0.2.0/wandb_gql/client.py", line 52, in execute
    result = self._get_result(document, *args, **kwargs)
  File "/media/james/Projects/GitHub/DATA_340_NLP/venv/lib/python3.10/site-packages/wandb/vendor/gql-0.2.0/wandb_gql/client.py", line 60, in _get_result
    return self.transport.execute(document, *args, **kwargs)
  File "/media/james/Projects/GitHub/DATA_340_NLP/venv/lib/python3.10/site-packages/wandb/sdk/lib/gql_request.py", line 59, in execute
    request.raise_for_status()
  File "/media/james/Projects/GitHub/DATA_340_NLP/venv/lib/python3.10/site-packages/requests/models.py", line 1021, in raise_for_status
    raise HTTPError(http_error_msg, response=self)
requests.exceptions.HTTPError: 404 Client Error: Not Found for url: https://api.wandb.ai/graphql

During handling of the above exception, another exception occurred:

Traceback (most recent call last):
  File "/media/james/Projects/GitHub/DATA_340_NLP/venv/lib/python3.10/site-packages/wandb/sdk/internal/sender.py", line 969, in send_run
    server_run = self._init_run(run, config_value_dict)
  File "/media/james/Projects/GitHub/DATA_340_NLP/venv/lib/python3.10/site-packages/wandb/sdk/internal/sender.py", line 1014, in _init_run
    server_run, inserted, server_messages = self._api.upsert_run(
  File "/media/james/Projects/GitHub/DATA_340_NLP/venv/lib/python3.10/site-packages/wandb/apis/normalize.py", line 73, in wrapper
    raise err
  File "/media/james/Projects/GitHub/DATA_340_NLP/venv/lib/python3.10/site-packages/wandb/apis/normalize.py", line 41, in wrapper
    return func(*args, **kwargs)
  File "/media/james/Projects/GitHub/DATA_340_NLP/venv/lib/python3.10/site-packages/wandb/sdk/internal/internal_api.py", line 2217, in upsert_run
    response = self.gql(
  File "/media/james/Projects/GitHub/DATA_340_NLP/venv/lib/python3.10/site-packages/wandb/sdk/internal/internal_api.py", line 341, in gql
    ret = self._retry_gql(
  File "/media/james/Projects/GitHub/DATA_340_NLP/venv/lib/python3.10/site-packages/wandb/sdk/lib/retry.py", line 147, in __call__
    retry_timedelta_triggered = check_retry_fn(e)
  File "/media/james/Projects/GitHub/DATA_340_NLP/venv/lib/python3.10/site-packages/wandb/util.py", line 968, in check_retry_fn
    return fallback_retry_fn(e)
  File "/media/james/Projects/GitHub/DATA_340_NLP/venv/lib/python3.10/site-packages/wandb/util.py", line 910, in no_retry_auth
    raise CommError(
wandb.errors.CommError: It appears that you do not have permission to access the requested resource. Please reach out to the project owner to grant you access. If you have the correct permissions, verify that there are no issues with your networking setup.(Error 404: Not Found)
2024-03-26 14:13:54,489 DEBUG   HandlerThread:1607159 [handler.py:handle_request():146] handle_request: status_report
2024-03-26 14:13:57,790 DEBUG   HandlerThread:1607159 [handler.py:handle_request():146] handle_request: status_report
